Workbook

Sheet Sheet1
A1: SampleID | B1: Labcode | C1: Label | D1: Class | E1: Type | F1: Subtype | G1: Age | H1: Gender | I1: Stage | J1: Stage short | K1: Source | L1: V plasma | M1: V elution | N1: cfDNA conc | O1: cfDNA yield (ng cfDNA / 1 ml plasma) | P1: Input | Q1: Input class | R1: Run | S1: MEAN_COVERAGE | T1: PCT_EXC_DUPE | U1: mapped_percent | V1: total_reads
A2: HNGH001 | B2: HNGH001 | C2: 0 | D2: 0 | E2: Healthy | G2: 54 | H2: M | J2: NA | K2: Gastric Dr Dung | L2: 2 | M2: 30 | N2: 0.325 | O2: 4.875 | P2: 4.875 | Q2: x>=3 | R2: R6885 | S2: 0.460118 | T2: 0.006424 | U2: 99.54 | V2: 30215218
A3: HNGH002 | B3: HNGH002 | C3: 0 | D3: 0 | E3: Healthy | G3: 63 | H3: F | J3: NA | K3: Gastric Dr Dung | L3: 2 | M3: 30 | N3: 0.258 | O3: 3.87 | P3: 4.644 | Q3: x>=3 | R3: R6885 | S3: 0.54829 | T3: 0.006334 | U3: 99.64 | V3: 35741446
A4: HNGH003 | B4: HNGH003 | C4: 0 | D4: 0 | E4: Healthy | G4: 37 | H4: M | J4: NA | K4: Gastric Dr Dung | L4: 2 | M4: 30 | N4: 0.153 | O4: 2.295 | P4: 2.754 | Q4: 2<=x<3 | R4: R6885 | S4: 0.554072 | T4: 0.006655 | U4: 99.6 | V4: 36445858
A5: HNGH004 | B5: HNGH004 | C5: 0 | D5: 0 | E5: Healthy | G5: 63 | H5: M | J5: NA | K5: Gastric Dr Dung | L5: 2 | M5: 30 | N5: 0.337 | O5: 5.055 | P5: 4.718 | Q5: x>=3 | R5: R6898 | S5: 0.538871 | T5: 0.0063 | U5: 99.52 | V5: 35509388
A6: HNGH005 | B6: HNGH005 | C6: 0 | D6: 0 | E6: Healthy | G6: 61 | H6: F | J6: NA | K6: Gastric Dr Dung | L6: 1.5 | M6: 30 | N6: 0.498 | O6: 9.96 | P6: 4.98 | Q6: x>=3 | R6: R6914 | S6: 0.502258 | T6: 0.006196 | U6: 99.63 | V6: 32820623
A7: HNGH006 | B7: HNGH006 | C7: 0 | D7: 0 | E7: Healthy | G7: 66 | H7: M | J7: NA | K7: Gastric Dr Dung | L7: 2 | M7: 30 | N7: 0.882 | O7: 13.23 | P7: 4.41 | Q7: x>=3 | R7: R6914 | S7: 0.655836 | T7: 0.007746 | U7: 99.41 | V7: 43108676
A8: HNGH007 | B8: HNGH007 | C8: 0 | D8: 0 | E8: Healthy | G8: 48 | H8: F | J8: NA | K8: Gastric Dr Dung | L8: 2 | M8: 30 | N8: 0.645 | O8: 9.675 | P8: 4.515 | Q8: x>=3 | R8: R6914 | S8: 0.702234 | T8: 0.006975 | U8: 99.63 | V8: 45804074
A9: HNGH008 | B9: HNGH008 | C9: 0 | D9: 0 | E9: Healthy | G9: 40 | H9: M | J9: NA | K9: Gastric Dr Dung | L9: 2 | M9: 30 | N9: 0.49 | O9: 7.35 | P9: 4.9 | Q9: x>=3 | R9: R6914 | S9: 0.595394 | T9: 0.006908 | U9: 99.57 | V9: 39243030
A10: HNGH009 | B10: HNGH009 | C10: 0 | D10: 0 | E10: Healthy | G10: 44 | H10: M | J10: NA | K10: Gastric Dr Dung | L10: 1.8 | M10: 30 | N10: 0.469 | O10: 7.8166667 | P10: 4.69 | Q10: x>=3 | R10: R6914 | S10: 0.445259 | T10: 0.006292 | U10: 99.57 | V10: 29351340
A11: HNGH010 | B11: HNGH010 | C11: 0 | D11: 0 | E11: Healthy | G11: 41 | H11: F | J11: NA | K11: Gastric Dr Dung | L11: 2 | M11: 30 | N11: 0.263 | O11: 3.945 | P11: 4.734 | Q11: x>=3 | R11: R6914 | S11: 0.594517 | T11: 0.006092 | U11: 99.63 | V11: 38776752
A12: HNGH011 | B12: HNGH011 | C12: 0 | D12: 0 | E12: Healthy | G12: 53 | H12: M | J12: NA | K12: Gastric Dr Dung | L12: 1.8 | M12: 30 | N12: 0.491 | O12: 8.1833333 | P12: 4.91 | Q12: x>=3 | R12: R6914 | S12: 0.55277 | T12: 0.005696 | U12: 99.54 | V12: 36343719
A13: HNGH012 | B13: HNGH012 | C13: 0 | D13: 0 | E13: Healthy | G13: 60 | H13: M | J13: NA | K13: Gastric Dr Dung | L13: 1.5 | M13: 30 | N13: 0.39 | O13: 7.8 | P13: 4.68 | Q13: x>=3 | R13: R6914 | S13: 0.601377 | T13: 0.007063 | U13: 99.56 | V13: 39495594
... A22: HNGH021 | B22: HNGH021 | C22: 0 | D22: 0 | E22: Healthy | G22: 45 | H22: F | J22: NA | K22: Gastric Dr Dung | L22: 1.9 | M22: 30 | N22: 0.408 | O22: 6.4421053 | P22: 4.896 | Q22: x>=3 | R22: R7057 | S22: 0.341635 | T22: 0.006092 | U22: 99.62 | V22: 22366609
A23: HNGH022 | B23: HNGH022 | C23: #N/A | D23: #N/A | E23: Gastric_highrisk | G23: 49 | H23: F | J23: NA | K23: Gastric Dr Dung | L23: 2 | M23: 30 | N23: 0.462 | O23: 6.93 | P23: 4.851 | Q23: x>=3 | R23: R7073 | S23: 0.534842 | T23: 0.008276 | U23: 99.63 | V23: 34943102
A24: HNGH023 | B24: HNGH023 | C24: #N/A | D24: #N/A | E24: Gastric_highrisk | G24: 41 | H24: M | J24: NA | K24: Gastric Dr Dung | L24: 2 | M24: 30 | N24: 0.423 | O24: 6.345 | P24: 4.8645 | Q24: x>=3 | R24: R7073 | S24: 0.529241 | T24: 0.01082 | U24: 99.53 | V24: 34909292
A25: HNGH024 | B25: HNGH024 | C25: 0 | D25: 0 | E25: Healthy | G25: 54 | H25: M | J25: NA | K25: Gastric Dr Dung | L25: 2 | M25: 30 | N25: 0.734 | O25: 11.01 | P25: 4.404 | Q25: x>=3 | R25: R6958 | S25: 0.315615 | T25: 0.010651 | U25: 99.55 | V25: 20867049
A26: HNGH025 | B26: HNGH025 | C26: #N/A | D26: #N/A | E26: Healthy_khongnoisoi | G26: 56 | H26: F | J26: NA | K26: Gastric Dr Dung | L26: 1.9 | M26: 30 | N26: 0.294 | O26: 4.6421053 | P26: 4.998 | Q26: x>=3 | R26: R6958 | S26: 0.277116 | T26: 0.009676 | U26: 99.62 | V26: 18147246
A27: HNGH026 | B27: HNGH026 | C27: 0 | D27: 0 | E27: Healthy | G27: 43 | H27: M | J27: NA | K27: Gastric Dr Dung | L27: 1.5 | M27: 30 | N27: 0.331 | O27: 6.62 | P27: 4.965 | Q27: x>=3 | R27: R6958 | S27: 0.297606 | T27: 0.01114 | U27: 99.57 | V27: 19608324
A28: HNGH027 | B28: HNGH027 | C28: 0 | D28: 0 | E28: Healthy | G28: 38 | H28: M | J28: NA | K28: Gastric Dr Dung | L28: 2 | M28: 30 | N28: 0.512 | O28: 7.68 | P28: 4.608 | Q28: x>=3 | R28: R6958 | S28: 0.416885 | T28: 0.01016 | U28: 99.57 | V28: 27413051
A29: HNGH028 | B29: HNGH028 | C29: 0 | D29: 0 | E29: Healthy | G29: 63 | H29: F | J29: NA | K29: Gastric Dr Dung | L29: 1.5 | M29: 30 | N29: 0.473 | O29: 9.46 | P29: 4.73 | Q29: x>=3 | R29: R6958 | S29: 0.382742 | T29: 0.009041 | U29: 99.6 | V29: 25112817
A30: HNGH029 | B30: HNGH029 | C30: 0 | D30: 0 | E30: Healthy | G30: 58 | H30: F | J30: NA | K30: Gastric Dr Dung | L30: 1.5 | M30: 30 | N30: 0.323 | O30: 6.46 | P30: 4.845 | Q30: x>=3 | R30: R6958 | S30: 0.289796 | T30: 0.009124 | U30: 99.62 | V30: 18923741
A31: HNGH030 | B31: HNGH030 | C31: 0 | D31: 0 | E31: Healthy | G31: 64 | H31: F | J31: NA | K31: Gastric Dr Dung | L31: 1.7 | M31: 30 | N31: 1.11 | O31: 19.588235 | P31: 4.995 | Q31: x>=3 | R31: R6958 | S31: 0.399722 | T31: 0.012504 | U31: 99.61 | V31: 26240322
A32: HNGH031 | B32: HNGH031 | C32: 1 | D32: 4 | E32: Gastric | G32: 75 | H32: M | J32: NA | K32: Gastric Dr Dung | L32: 1.8 | M32: 30 | N32: 0.404 | O32: 6.7333333 | P32: 4.848 | Q32: x>=3 | R32: R7073 | S32: 0.52542 | T32: 0.007737 | U32: 99.55 | V32: 34692926
A33: HNGH032 | B33: HNGH032 | C33: 0 | D33: 0 | E33: Healthy | G33: 55 | H33: M | J33: NA | K33: Gastric Dr Dung | L33: 1.7 | M33: 30 | N33: 0.572 | O33: 10.094118 | P33: 4.862 | Q33: x>=3 | R33: R7073 | S33: 0.543498 | T33: 0.008369 | U33: 99.6 | V33: 35719789
A34: HNGH033 | B34: HNGH033 | C34: 0 | D34: 0 | E34: Healthy | G34: 48 | H34: F | J34: NA | K34: Gastric Dr Dung | L34: 1.7 | M34: 30 | N34: 0.247 | O34: 4.3588235 | P34: 4.446 | Q34: x>=3 | R34: R7073 | S34: 0.498396 | T34: 0.008509 | U34: 99.62 | V34: 32704685
A35: HNGH034 | B35: HNGH034 | C35: #N/A | D35: #N/A | E35: Healthy_khongnoisoi | G35: 67 | H35: M | J35: NA | K35: Gastric Dr Dung | L35: 1.5 | M35: 30 | N35: 0.569 | O35: 11.38 | P35: 4.8365 | Q35: x>=3 | R35: R7073 | S35: 0.552786 | T35: 0.007522 | U35: 99.6 | V35: 36290020
A36: HNGH035 | B36: HNGH035 | C36: 0 | D36: 0 | E36: Healthy | G36: 68 | H36: F | J36: NA | K36: Gastric Dr Dung | L36: 2 | M36: 30 | N36: 0.445 | O36: 6.675 | P36: 4.895 | Q36: x>=3 | R36: R6958 | S36: 0.320722 | T36: 0.009338 | U36: 99.58 | V36: 21049423
A37: HNGH036 | B37: HNGH036 | C37: 0 | D37: 0 | E37: Healthy | G37: 49 | H37: M | J37: NA | K37: Gastric Dr Dung | L37: 2 | M37: 30 | N37: 0.211 | O37: 3.165 | P37: 3.798 | Q37: x>=3 | R37: R6958 | S37: 0.267569 | T37: 0.010479 | U37: 99.55 | V37: 17689869
A38: HNGH037 | B38: HNGH037 | C38: 0 | D38: 0 | E38: Healthy | G38: 54 | H38: M | J38: NA | K38: Gastric Dr Dung | L38: 2 | M38: 30 | N38: 0.566 | O38: 8.49 | P38: 4.811 | Q38: x>=3 | R38: R6958 | S38: 0.379367 | T38: 0.010582 | U38: 99.57 | V38: 24959516
A39: HNGH038 | B39: HNGH038 | C39: 0 | D39: 0 | E39: Healthy | G39: 60 | H39: F | J39: NA | K39: Gastric Dr Dung | L39: 2 | M39: 30 | N39: 0.249 | O39: 3.735 | P39: 4.482 | Q39: x>=3 | R39: R6958 | S39: 0.270475 | T39: 0.009743 | U39: 99.59 | V39: 17746553
A40: HNGH039 | B40: HNGH039 | C40: 0 | D40: 0 | E40: Healthy | G40: 61 | H40: F | J40: NA | K40: Gastric Dr Dung | L40: 1.5 | M40: 30 | N40: 0.302 | O40: 6.04 | P40: 4.832 | Q40: x>=3 | R40: R6987 | S40: 0.499973 | T40: 0.005948 | U40: 99.64 | V40: 32676907
A41: HNGH040 | B41: HNGH040 | C41: 0 | D41: 0 | E41: Healthy | G41: 50 | H41: F | J41: NA | K41: Gastric Dr Dung | L41: 1.5 | M41: 30 | N41: 0.322 | O41: 6.44 | P41: 4.83 | Q41: x>=3 | R41: R6987 | S41: 0.643437 | T41: 0.006869 | U41: 99.62 | V41: 42211195
A42: HNGH041 | B42: HNGH041 | C42: 0 | D42: 0 | E42: Healthy | G42: 46 | H42: F | J42: NA | K42: Gastric Dr Dung | L42: 2 | M42: 30 | N42: 0.21 | O42: 3.15 | P42: 3.78 | Q42: x>=3 | R42: R6987 | S42: 0.512426 | T42: 0.005767 | U42: 99.62 | V42: 33500419
A43: HNGH042 | B43: HNGH042 | C43: 0 | D43: 0 | E43: Healthy | G43: 61 | H43: F | J43: NA | K43: Gastric Dr Dung | L43: 1.8 | M43: 30 | N43: 0.334 | O43: 5.5666667 | P43: 4.843 | Q43: x>=3 | R43: R6987 | S43: 0.572425 | T43: 0.005815 | U43: 99.62 | V43: 37384990
A44: HNGH043 | B44: HNGH043 | C44: 0 | D44: 0 | E44: Healthy | G44: 63 | H44: M | J44: NA | K44: Gastric Dr Dung | L44: 2 | M44: 30 | N44: 0.607 | O44: 9.105 | P44: 4.856 | Q44: x>=3 | R44: R6973 | S44: 0.428507 | T44: 0.00745 | U44: 99.56 | V44: 28233420
A45: HNGH044 | B45: HNGH044 | C45: 0 | D45: 0 | E45: Healthy | G45: 53 | H45: M | J45: NA | K45: Gastric Dr Dung | L45: 2 | M45: 30 | N45: 0.423 | O45: 6.345 | P45: 4.8645 | Q45: x>=3 | R45: R6973 | S45: 0.478096 | T45: 0.008404 | U45: 99.56 | V45: 31380943
A46: HNGH045 | B46: HNGH045 | C46: 0 | D46: 0 | E46: Healthy | G46: 56 | H46: M | J46: NA | K46: Gastric Dr Dung | L46: 2 | M46: 30 | N46: 0.329 | O46: 4.935 | P46: 4.935 | Q46: x>=3 | R46: R6973 | S46: 0.520086 | T46: 0.00915 | U46: 99.55 | V46: 34360292
A47: HNGH046 | B47: HNGH046 | C47: 0 | D47: 0 | E47: Healthy | G47: 59 | H47: F | J47: NA | K47: Gastric Dr Dung | L47: 1.5 | M47: 30 | N47: 0.405 | O47: 8.1 | P47: 4.86 | Q47: x>=3 | R47: R6973 | S47: 0.484236 | T47: 0.008277 | U47: 99.6 | V47: 31737150
... A50: HNGH049 | B50: HNGH049 | C50: 0 | D50: 0 | E50: Healthy | G50: 40 | H50: M | J50: NA | K50: Gastric Dr Dung | L50: 2 | M50: 30 | N50: 0.747 | O50: 11.205 | P50: 4.8555 | Q50: x>=3 | R50: R6973 | S50: 0.545921 | T50: 0.008402 | U50: 99.53 | V50: 36067535
...

Sheet Sheet2
B1: Tổng số mẫu đã nhận | C1: Tổng số đã chạy | D1: Sẽ chạy
A2: Gastric cancer | B2: =COUNTIF(Sheet1!E:E,"Gastric") -> 58 | C2: =COUNTIFS(Sheet1!E:E,"Gastric",Sheet1!P:P,"Yes") -> 0 | D2: =B2-C2 -> 58
A3: Gastric cancer thu sai quy cách | B3: =COUNTIF(Sheet1!E:E,"Gastric_thumausai") -> 28 | C3: =COUNTIFS(Sheet1!E:E,"Gastric_thumausai",Sheet1!P:P,"Yes") -> 0 | D3: =B3-C3 -> 28
A4: Healthy control | B4: =COUNTIF(Sheet1!E:E,"Healthy") -> 67 | C4: =COUNTIFS(Sheet1!E:E,"Healthy",Sheet1!P:P,"Yes") -> 0 | D4: =B4-C4 -> 67
A5: Healthy control thu sai quy cách | B5: =COUNTIF(Sheet1!E:E,"Healthy_thumausai") -> 1 | C5: =COUNTIFS(Sheet1!E:E,"Healthy_thumausai",Sheet1!P:P,"Yes") -> 0 | D5: =B5-C5 -> 1

Sheet Sheet3
A1: Personel | B1: 9102024 | C1: Labcode | D1: cfDNA concentration (ng/ul) | E1: Notes | F1: V plasma | G1: Cohort | H1: Quy trình tách | I1: Quy trình chạy | J1: Vị trí cất plasma | K1: Ng | L1: Đã dùng | M1: Còn lại | N1: Quyet dinh | O1: V plasma đã dùng
B2: ET26-14 | C2: HNGH001 | D2: 0.325 | F2: 2 | G2: Gastric Dr Dung | H2: Tách tay | I2: nonBS | K2: =D2*25 -> 8.125 | L2: =IF(5/D2>18,18,5/D2) -> 15.384615 | M2: =(25-L2)*D2 -> 3.125 | N2: Chạy | O2: 2
B3: ET26-15 | C3: HNGH002 | D3: 0.258 | F3: 2 | G3: Gastric Dr Dung | H3: Tách tay | I3: nonBS | K3: =D3*25 -> 6.45 | L3: =IF(5/D3>18,18,5/D3) -> 18 | M3: =(25-L3)*D3 -> 1.806 | N3: Tách lại | O3: 2
B4: ET26-16 | C4: HNGH003 | D4: 0.153 | F4: 2 | G4: Gastric Dr Dung | H4: Tách tay | I4: nonBS | K4: =D4*25 -> 3.825 | L4: =IF(5/D4>18,18,5/D4) -> 18 | M4: =(25-L4)*D4 -> 1.071 | N4: Tách lại | O4: 2
B5: ET30-4 | C5: HNGH005 | D5: 0.498 | E5: 12.45 | F5: 1.5 | G5: Gastric Dr Dung | H5: Tách máy 2ml | I5: nonBS | K5: =D5*25 -> 12.45 | L5: =IF(5/D5>18,18,5/D5) -> 10.040161 | M5: =(25-L5)*D5 -> 7.45 | N5: Chạy | O5: 1.5
B6: ET30-5 | C6: HNGH006 | D6: 0.882 | E6: 22.05 | F6: 2 | G6: Gastric Dr Dung | H6: Tách máy 2ml | I6: nonBS | J6: Hộp HNGH, Tầng 2 trên xuống, cây 1 phải sang, khay 2 dưới lên | K6: =D6*25 -> 22.05 | L6: =IF(5/D6>18,18,5/D6) -> 5.6689342 | M6: =(25-L6)*D6 -> 17.05 | N6: Chạy | O6: 2
B7: ET30-6 | C7: HNGH007 | D7: 0.645 | E7: 16.125 | F7: 2 | G7: Gastric Dr Dung | H7: Tách máy 2ml | I7: nonBS | J7: Hộp HNGH, Tầng 2 trên xuống, cây 1 phải sang, khay 2 dưới lên | K7: =D7*25 -> 16.125 | L7: =IF(5/D7>18,18,5/D7) -> 7.751938 | M7: =(25-L7)*D7 -> 11.125 | N7: Chạy | O7: 2
B8: ET30-7 | C8: HNGH008 | D8: 0.49 | E8: 12.25 | F8: 2 | G8: Gastric Dr Dung | H8: Tách máy 2ml | I8: nonBS | J8: Hộp HNGH, Tầng 2 trên xuống, cây 1 phải sang, khay 2 dưới lên | K8: =D8*25 -> 12.25 | L8: =IF(5/D8>18,18,5/D8) -> 10.204082 | M8: =(25-L8)*D8 -> 7.25 | N8: Chạy | O8: 2
B9: ET30-8 | C9: HNGH009 | D9: 0.469 | E9: 11.725 | F9: 1.8 | G9: Gastric Dr Dung | H9: Tách máy 2ml | I9: nonBS | J9: Hộp HNGH, Tầng 2 trên xuống, cây 1 phải sang, khay 2 dưới lên | K9: =D9*25 -> 11.725 | L9: =IF(5/D9>18,18,5/D9) -> 10.660981 | M9: =(25-L9)*D9 -> 6.725 | N9: Chạy | O9: 1.8
B10: ET30-9 | C10: HNGH010 | D10: 0.263 | E10: 6.575 | F10: 2 | G10: Gastric Dr Dung | H10: Tách máy 2ml | I10: nonBS | J10: Hộp HNGH, Tầng 2 trên xuống, cây 1 phải sang, khay 2 dưới lên | K10: =D10*25 -> 6.575 | L10: =IF(5/D10>18,18,5/D10) -> 18 | M10: =(25-L10)*D10 -> 1.841 | N10: Tách lại | O10: 2
B11: ET30-10 | C11: HNGH011 | D11: 0.491 | E11: 12.275 | F11: 1.8 | G11: Gastric Dr Dung | H11: Tách máy 2ml | I11: nonBS | J11: Hộp HNGH, Tầng 2 trên xuống, cây 1 phải sang, khay 2 dưới lên | K11: =D11*25 -> 12.275 | L11: =IF(5/D11>18,18,5/D11) -> 10.183299 | M11: =(25-L11)*D11 -> 7.275 | N11: Chạy | O11: 1.8
B12: ET30-11 | C12: HNGH012 | D12: 0.39 | E12: 9.75 | F12: 1.5 | G12: Gastric Dr Dung | H12: Tách máy 2ml | I12: nonBS | J12: Hộp HNGH, Tầng 2 trên xuống, cây 1 phải sang, khay 2 dưới lên | K12: =D12*25 -> 9.75 | L12: =IF(5/D12>18,18,5/D12) -> 12.820513 | M12: =(25-L12)*D12 -> 4.75 | N12: Chạy | O12: 1.5
B13: ET30-12 | C13: HNGH013 | D13: 0.364 | E13: 9.1 | F13: 2 | G13: Gastric Dr Dung | H13: Tách máy 2ml | I13: nonBS | J13: Hộp HNGH, Tầng 2 trên xuống, cây 1 phải sang, khay 2 dưới lên | K13: =D13*25 -> 9.1 | L13: =IF(5/D13>18,18,5/D13) -> 13.736264 | M13: =(25-L13)*D13 -> 4.1 | N13: Chạy | O13: 2
B14: ET30-13 | C14: HNGH014 | D14: 0.402 | E14: 10.05 | F14: 2 | G14: Gastric Dr Dung | H14: Tách máy 2ml | I14: nonBS | J14: Hộp HNGH, Tầng 2 trên xuống, cây 1 phải sang, khay 2 dưới lên | K14: =D14*25 -> 10.05 | L14: =IF(5/D14>18,18,5/D14) -> 12.437811 | M14: =(25-L14)*D14 -> 5.05 | N14: Chạy | O14: 2
B15: ET30-14 | C15: HNGH015 | D15: 0.572 | E15: 14.3 | F15: 2 | G15: Gastric Dr Dung | H15: Tách máy 2ml | I15: nonBS | J15: Hộp HNGH, Tầng 2 trên xuống, cây 1 phải sang, khay 2 dưới lên | K15: =D15*25 -> 14.3 | L15: =IF(5/D15>18,18,5/D15) -> 8.7412587 | M15: =(25-L15)*D15 -> 9.3 | N15: Chạy | O15: 2
B16: ET30-15 | C16: HNGH016 | D16: 0.798 | E16: 19.95 | F16: 1.8 | G16: Gastric Dr Dung | H16: Tách máy 2ml | I16: nonBS | J16: Hộp HNGH, Tầng 2 trên xuống, cây 1 phải sang, khay 2 dưới lên | K16: =D16*25 -> 19.95 | L16: =IF(5/D16>18,18,5/D16) -> 6.2656642 | M16: =(25-L16)*D16 -> 14.95 | N16: Chạy | O16: 1.8
B17: ET31-23 | C17: HNGH017 | D17: 0.388 | F17: 1.7 | G17: Gastric Dr Dung | I17: nonBS | J17: 9.7 | K17: =D17*25 -> 9.7 | L17: =IF(5/D17>18,18,5/D17) -> 12.886598 | M17: =(25-L17)*D17 -> 4.7 | N17: Chạy | O17: 1.7
B18: ET31-24 | C18: HNGH018 | D18: 0.875 | F18: 1.7 | G18: Gastric Dr Dung | I18: nonBS | J18: 21.875 | K18: =D18*25 -> 21.875 | L18: =IF(5/D18>18,18,5/D18) -> 5.7142857 | M18: =(25-L18)*D18 -> 16.875 | N18: Chạy | O18: 1.7
B19: ET41-16 | C19: HNGH019 | D19: 1.25 | E19: 16 | F19: 2 | G19: Gastric Dr Dung | H19: Tách máy 2ml | I19: nonBS | K19: =D19*25 -> 31.25 | L19: =IF(5/D19>18,18,5/D19) -> 4 | M19: =(25-L19)*D19 -> 26.25 | N19: Chạy | O19: 2
B20: ET41-17 | C20: HNGH020 | D20: 0.311 | E20: 17 | F20: 1.9 | G20: Gastric Dr Dung | H20: Tách máy 2ml | I20: nonBS | K20: =D20*25 -> 7.775 | L20: =IF(5/D20>18,18,5/D20) -> 16.07717 | M20: =(25-L20)*D20 -> 2.775 | N20: Chạy | O20: 1.9
B21: ET41-18 | C21: HNGH021 | D21: 0.408 | E21: 18 | F21: 1.9 | G21: Gastric Dr Dung | H21: Tách máy 2ml | I21: nonBS | K21: =D21*25 -> 10.2 | L21: =IF(5/D21>18,18,5/D21) -> 12.254902 | M21: =(25-L21)*D21 -> 5.2 | N21: Chạy | O21: 1.9
B22: ET41-19 | C22: HNGH022 | D22: 0.462 | E22: 19 | F22: 2 | G22: Gastric Dr Dung | H22: Tách máy 2ml | I22: nonBS | K22: =D22*25 -> 11.55 | L22: =IF(5/D22>18,18,5/D22) -> 10.822511 | M22: =(25-L22)*D22 -> 6.55 | N22: Chạy | O22: 2
B23: ET41-20 | C23: HNGH023 | D23: 0.423 | E23: 20 | F23: 2 | G23: Gastric Dr Dung | H23: Tách máy 2ml | I23: nonBS | K23: =D23*25 -> 10.575 | L23: =IF(5/D23>18,18,5/D23) -> 11.820331 | M23: =(25-L23)*D23 -> 5.575 | N23: Chạy | O23: 2
A24: Luyen | B24: ET32-20 | C24: HNGH024 | D24: 0.734 | E24: 20 | F24: 2 | G24: Gastric Dr Dung | I24: nonBS | K24: =D24*25 -> 18.35 | L24: =IF(5/D24>18,18,5/D24) -> 6.8119891 | M24: =(25-L24)*D24 -> 13.35 | N24: Chạy | O24: 2
B25: ET32-21 | C25: HNGH025 | D25: 0.294 | E25: 21 | F25: 1.9 | G25: Gastric Dr Dung | I25: nonBS | K25: =D25*25 -> 7.35 | L25: =IF(5/D25>18,18,5/D25) -> 17.006803 | M25: =(25-L25)*D25 -> 2.35 | N25: Chạy | O25: 1.9
B26: ET32-22 | C26: HNGH026 | D26: 0.331 | E26: 22 | F26: 1.5 | G26: Gastric Dr Dung | I26: nonBS | K26: =D26*25 -> 8.275 | L26: =IF(5/D26>18,18,5/D26) -> 15.10574 | M26: =(25-L26)*D26 -> 3.275 | N26: Chạy | O26: 1.5
B27: ET32-23 | C27: HNGH027 | D27: 0.512 | E27: 23 | F27: 2 | G27: Gastric Dr Dung | I27: nonBS | K27: =D27*25 -> 12.8 | L27: =IF(5/D27>18,18,5/D27) -> 9.765625 | M27: =(25-L27)*D27 -> 7.8 | N27: Chạy | O27: 2
B28: ET32-24 | C28: HNGH028 | D28: 0.473 | E28: 24 | F28: 1.5 | G28: Gastric Dr Dung | I28: nonBS | K28: =D28*25 -> 11.825 | L28: =IF(5/D28>18,18,5/D28) -> 10.570825 | M28: =(25-L28)*D28 -> 6.825 | N28: Chạy | O28: 1.5
B29: ET32-25 | C29: HNGH029 | D29: 0.323 | E29: 25 | F29: 1.5 | G29: Gastric Dr Dung | I29: nonBS | K29: =D29*25 -> 8.075 | L29: =IF(5/D29>18,18,5/D29) -> 15.479876 | M29: =(25-L29)*D29 -> 3.075 | N29: Chạy | O29: 1.5
B30: ET32-26 | C30: HNGH030 | D30: 1.11 | E30: 26 | F30: 1.7 | G30: Gastric Dr Dung | I30: nonBS | K30: =D30*25 -> 27.75 | L30: =IF(5/D30>18,18,5/D30) -> 4.5045045 | M30: =(25-L30)*D30 -> 22.75 | N30: Chạy | O30: 1.7
B31: ET41-21 | C31: HNGH031 | D31: 0.404 | E31: 21 | F31: 1.8 | G31: Gastric Dr Dung | H31: Tách máy 2ml | I31: nonBS | K31: =D31*25 -> 10.1 | L31: =IF(5/D31>18,18,5/D31) -> 12.376238 | M31: =(25-L31)*D31 -> 5.1 | N31: Chạy | O31: 1.8
B32: ET41-22 | C32: HNGH032 | D32: 0.572 | E32: 22 | F32: 1.7 | G32: Gastric Dr Dung | H32: Tách máy 2ml | I32: nonBS | K32: =D32*25 -> 14.3 | L32: =IF(5/D32>18,18,5/D32) -> 8.7412587 | M32: =(25-L32)*D32 -> 9.3 | N32: Chạy | O32: 1.7
B33: ET41-23 | C33: HNGH033 | D33: 0.247 | E33: 23 | F33: 1.7 | G33: Gastric Dr Dung | H33: Tách máy 2ml | I33: nonBS | K33: =D33*25 -> 6.175 | L33: =IF(5/D33>18,18,5/D33) -> 18 | M33: =(25-L33)*D33 -> 1.729 | N33: Tách lại | O33: 1.7
B34: ET41-24 | C34: HNGH034 | D34: 0.569 | E34: 24 | F34: 1.5 | G34: Gastric Dr Dung | H34: Tách máy 2ml | I34: nonBS | K34: =D34*25 -> 14.225 | L34: =IF(5/D34>18,18,5/D34) -> 8.7873462 | M34: =(25-L34)*D34 -> 9.225 | N34: Chạy | O34: 1.5
B35: ET33-27 | C35: HNGH035 | D35: 0.445 | E35: 11.125 | F35: 2 | G35: Gastric Dr Dung | H35: Tách máy 2ml | I35: NonBS | K35: =D35*25 -> 11.125 | L35: =IF(5/D35>18,18,5/D35) -> 11.235955 | M35: =(25-L35)*D35 -> 6.125 | N35: Chạy | O35: 2
B36: ET33-28 | C36: HNGH036 | D36: 0.211 | E36: 5.275 | F36: 2 | G36: Gastric Dr Dung | H36: Tách máy 2ml | I36: NonBS | K36: =D36*25 -> 5.275 | L36: =IF(5/D36>18,18,5/D36) -> 18 | M36: =(25-L36)*D36 -> 1.477 | N36: Tách lại | O36: 2
B37: ET33-29 | C37: HNGH037 | D37: 0.566 | E37: 14.15 | F37: 2 | G37: Gastric Dr Dung | H37: Tách máy 2ml | I37: NonBS | K37: =D37*25 -> 14.15 | L37: =IF(5/D37>18,18,5/D37) -> 8.8339223 | M37: =(25-L37)*D37 -> 9.15 | N37: Chạy | O37: 2
B38: ET33-30 | C38: HNGH038 | D38: 0.249 | E38: 6.225 | F38: 2 | G38: Gastric Dr Dung | H38: Tách máy 2ml | I38: NonBS | K38: =D38*25 -> 6.225 | L38: =IF(5/D38>18,18,5/D38) -> 18 | M38: =(25-L38)*D38 -> 1.743 | N38: Tách lại | O38: 2
B39: ET35-28 | C39: HNGH039 | D39: 0.302 | E39: 28 | F39: 1.5 | G39: Gastric Dr Dung | H39: Tách máy 2ml | I39: NonBS | K39: =D39*25 -> 7.55 | L39: =IF(5/D39>18,18,5/D39) -> 16.556291 | M39: =(25-L39)*D39 -> 2.55 | N39: Chạy | O39: 1.5
B40: ET35-29 | C40: HNGH040 | D40: 0.322 | E40: 29 | F40: 1.5 | G40: Gastric Dr Dung | H40: Tách máy 2ml | I40: NonBS | K40: =D40*25 -> 8.05 | L40: =IF(5/D40>18,18,5/D40) -> 15.52795 | M40: =(25-L40)*D40 -> 3.05 | N40: Chạy | O40: 1.5
...

Sheet Sheet4
A1: Labcode | B1: V plasma đã dùng | C1: V plasma tổng | D1: V còn | E1: V sẽ tách | H1: Labcode | I1: Thể tích plasma
A2: HNGH002 | B2: 2 | C2: =VLOOKUP(A2,$H$2:$I$200,2,0) -> 5.4 | D2: =C2-B2 -> 3.4 | E2: 2 | H2: HNGK001 | I2: 3
A3: HNGH003 | B3: 2 | C3: =VLOOKUP(A3,$H$2:$I$200,2,0) -> 4.2 | D3: =C3-B3 -> 2.2 | E3: 1.2 | H3: HNGK002 | I3: 4.7
A4: HNGH010 | B4: 2 | C4: =VLOOKUP(A4,$H$2:$I$200,2,0) -> 4 | D4: =C4-B4 -> 2 | E4: 1 | H4: HNGK003 | I4: 4
A5: HNGH033 | B5: 1.7 | C5: =VLOOKUP(A5,$H$2:$I$200,2,0) -> 4.7 | D5: =C5-B5 -> 3 | E5: 2 | H5: HNGK004 | I5: 4.5
A6: HNGH036 | B6: 2 | C6: =VLOOKUP(A6,$H$2:$I$200,2,0) -> 4.6 | D6: =C6-B6 -> 2.6 | E6: 1.6 | H6: HNGK005 | I6: 4.7
A7: HNGH038 | B7: 2 | C7: =VLOOKUP(A7,$H$2:$I$200,2,0) -> 4.9 | D7: =C7-B7 -> 2.9 | E7: 1.9 | H7: HNGK006 | I7: 4.9
A8: HNGH041 | B8: 2 | C8: =VLOOKUP(A8,$H$2:$I$200,2,0) -> 4.2 | D8: =C8-B8 -> 2.2 | E8: 1.2 | H8: HNGK007 | I8: 3.9
A9: HNGH051 | B9: 2 | C9: =VLOOKUP(A9,$H$2:$I$200,2,0) -> 4.8 | D9: =C9-B9 -> 2.8 | E9: 1.8 | H9: HNGK008 | I9: 4.4
A10: HNGH052 | B10: 1.5 | C10: =VLOOKUP(A10,$H$2:$I$200,2,0) -> 3.5 | D10: =C10-B10 -> 2 | E10: 1 | H10: HNGK009 | I10: 5.3
A11: HNGH058 | B11: 1.6 | C11: =VLOOKUP(A11,$H$2:$I$200,2,0) -> 3.6 | D11: =C11-B11 -> 2 | E11: 1 | H11: HNGK010 | I11: 4.3
A12: HNGH062 | B12: 1.8 | C12: =VLOOKUP(A12,$H$2:$I$200,2,0) -> 4.8 | D12: =C12-B12 -> 3 | E12: 2 | H12: HNGK011 | I12: 4.2
A13: HNGK001 | B13: 1 | C13: =VLOOKUP(A13,$H$2:$I$200,2,0) -> 3 | D13: =C13-B13 -> 2 | E13: 1 | H13: HNGK012 | I13: 3.9
... A47: HNGK100 | B47: 1.8 | C47: =VLOOKUP(A47,$H$2:$I$200,2,0) -> 4.8 | D47: =C47-B47 -> 3 | E47: 2 | H47: HNGK046 | I47: 4.8
H48: HNGK047 | I48: 5.1
H49: HNGK048
H50: HNGK049 | I50: 4.7
H51: HNGK050 | I51: 4
H52: HNGK051 | I52: 4.4
H53: HNGK052 | I53: 5
H54: HNGK053 | I54: 3.7
H55: HNGK054 | I55: 5
H56: HNGK055 | I56: 5.5
H57: HNGK056 | I57: 4.5
H58: HNGK057 | I58: 5
H59: HNGK058 | I59: 5
H60: HNGK059 | I60: 4.5
H61: HNGK060 | I61: 5.6
... H106: HNGK105 | I106: 4.1
H107: HNGK106
H108: HNGH001 | I108: 4.5
H109: HNGH002 | I109: 5.4
H110: HNGH003 | I110: 4.2
H111: HNGH004 | I111: 4.4
H112: HNGH005 | I112: 4.5
H113: HNGH006 | I113: 3
H114: HNGH007 | I114: 5
H115: HNGH008 | I115: 4
H116: HNGH009 | I116: 3.8
H117: HNGH010 | I117: 4
...
